2024-08-15 23:19:55,081 ERROR Internal Server Error: /models/test/ None
2024-08-15 23:19:55,083 ERROR "GET /models/test/ HTTP/1.1" 500 0 None
2024-08-15 23:22:35,131 ERROR Internal Server Error: /models/test/ None
2024-08-15 23:22:35,133 ERROR "GET /models/test/ HTTP/1.1" 500 0 None
2024-08-15 23:32:09,647 ERROR Internal Server Error: /models/test/ None
2024-08-15 23:32:09,648 ERROR "GET /models/test/ HTTP/1.1" 500 0 None
2024-08-15 23:32:26,161 ERROR Internal Server Error: /models/test/ None
2024-08-15 23:32:26,162 ERROR "GET /models/test/ HTTP/1.1" 500 0 None
2024-08-15 23:32:49,441 ERROR Internal Server Error: /models/test/ (<class 'ZeroDivisionError'>, ZeroDivisionError('division by zero'), <traceback object at 0x00000260612F8F40>)
Traceback (most recent call last):
  File "B:\disk\learn\project\NewsPortal\venv\Lib\site-packages\django\core\handlers\exception.py", line 55, in inner
    response = get_response(request)
               ^^^^^^^^^^^^^^^^^^^^^
  File "B:\disk\learn\project\NewsPortal\venv\Lib\site-packages\django\core\handlers\base.py", line 197, in _get_response
    response = wrapped_callback(request, *callback_args, **callback_kwargs)
               ^^^^^^^^^^^^^^^^^^^^^^^^^^^^^^^^^^^^^^^^^^^^^^^^^^^^^^^^^^^^
  File "B:\disk\learn\project\NewsPortal\NewsPortal\NewsPortal\Models\views.py", line 239, in test
    name = 1/0
           ~^~
ZeroDivisionError: division by zero
2024-08-15 23:32:49,448 ERROR "GET /models/test/ HTTP/1.1" 500 74676 None
2024-08-15 23:36:21,581 ERROR Internal Server Error: /models/test/ None
2024-08-15 23:36:21,583 ERROR "GET /models/test/ HTTP/1.1" 500 0 None
2024-08-17 00:17:14,117 ERROR Internal Server Error: /models/test/ None
2024-08-17 00:17:14,118 ERROR "GET /models/test/ HTTP/1.1" 500 0 None
2024-08-17 21:04:54,176 ERROR Internal Server Error: /models/test/ None
2024-08-17 21:04:54,257 ERROR "GET /models/test/ HTTP/1.1" 500 59 None
2024-08-17 21:08:19,614 ERROR Internal Server Error: /models/test/ None
2024-08-17 21:08:19,639 ERROR "GET /models/test/ HTTP/1.1" 500 59 None
2024-08-17 21:13:58,669 ERROR Internal Server Error: /models/test/ None
2024-08-17 21:13:58,691 ERROR "GET /models/test/ HTTP/1.1" 500 0 None
2024-08-17 21:22:04,509 ERROR Internal Server Error: /models/test/ None
2024-08-17 21:22:04,530 ERROR "GET /models/test/ HTTP/1.1" 500 0 None
2024-08-17 21:26:54,626 ERROR Internal Server Error: /models/test/ None
2024-08-17 21:26:54,647 ERROR "GET /models/test/ HTTP/1.1" 500 0 None
2024-08-17 21:28:32,000 ERROR Internal Server Error: /models/test/ None
2024-08-17 21:28:32,022 ERROR "GET /models/test/ HTTP/1.1" 500 0 None
2024-08-17 21:33:57,802 ERROR Internal Server Error: /models/news/create/ (<class 'TypeError'>, TypeError('Model.save() takes from 1 to 5 positional arguments but 6 were given'), <traceback object at 0x00000258B6D708C0>)
Traceback (most recent call last):
  File "B:\disk\learn\project\NewsPortal\venv\Lib\site-packages\django\core\handlers\exception.py", line 55, in inner
    response = get_response(request)
               ^^^^^^^^^^^^^^^^^^^^^
  File "B:\disk\learn\project\NewsPortal\venv\Lib\site-packages\django\core\handlers\base.py", line 197, in _get_response
    response = wrapped_callback(request, *callback_args, **callback_kwargs)
               ^^^^^^^^^^^^^^^^^^^^^^^^^^^^^^^^^^^^^^^^^^^^^^^^^^^^^^^^^^^^
  File "B:\disk\learn\project\NewsPortal\venv\Lib\site-packages\django\views\generic\base.py", line 104, in view
    return self.dispatch(request, *args, **kwargs)
           ^^^^^^^^^^^^^^^^^^^^^^^^^^^^^^^^^^^^^^^
  File "B:\disk\learn\project\NewsPortal\venv\Lib\site-packages\django\contrib\auth\mixins.py", line 109, in dispatch
    return super().dispatch(request, *args, **kwargs)
           ^^^^^^^^^^^^^^^^^^^^^^^^^^^^^^^^^^^^^^^^^^
  File "B:\disk\learn\project\NewsPortal\venv\Lib\site-packages\django\views\generic\base.py", line 143, in dispatch
    return handler(request, *args, **kwargs)
           ^^^^^^^^^^^^^^^^^^^^^^^^^^^^^^^^^
  File "B:\disk\learn\project\NewsPortal\venv\Lib\site-packages\django\views\generic\edit.py", line 184, in post
    return super().post(request, *args, **kwargs)
           ^^^^^^^^^^^^^^^^^^^^^^^^^^^^^^^^^^^^^^
  File "B:\disk\learn\project\NewsPortal\venv\Lib\site-packages\django\views\generic\edit.py", line 153, in post
    return self.form_valid(form)
           ^^^^^^^^^^^^^^^^^^^^^
  File "B:\disk\learn\project\NewsPortal\NewsPortal\NewsPortal\Models\views.py", line 76, in form_valid
    post.save()
  File "B:\disk\learn\project\NewsPortal\NewsPortal\NewsPortal\Models\models.py", line 85, in save
    super().save(self, force_insert, force_update, using, update_fields)
TypeError: Model.save() takes from 1 to 5 positional arguments but 6 were given
2024-08-17 21:33:57,822 ERROR "POST /models/news/create/ HTTP/1.1" 500 106284 None
2024-08-17 21:38:27,033 ERROR Internal Server Error: /models/news/create/ (<class 'TypeError'>, TypeError('Model.save() takes from 1 to 5 positional arguments but 6 were given'), <traceback object at 0x00000258B6E0E6C0>)
Traceback (most recent call last):
  File "B:\disk\learn\project\NewsPortal\venv\Lib\site-packages\django\core\handlers\exception.py", line 55, in inner
    response = get_response(request)
               ^^^^^^^^^^^^^^^^^^^^^
  File "B:\disk\learn\project\NewsPortal\venv\Lib\site-packages\django\core\handlers\base.py", line 197, in _get_response
    response = wrapped_callback(request, *callback_args, **callback_kwargs)
               ^^^^^^^^^^^^^^^^^^^^^^^^^^^^^^^^^^^^^^^^^^^^^^^^^^^^^^^^^^^^
  File "B:\disk\learn\project\NewsPortal\venv\Lib\site-packages\django\views\generic\base.py", line 104, in view
    return self.dispatch(request, *args, **kwargs)
           ^^^^^^^^^^^^^^^^^^^^^^^^^^^^^^^^^^^^^^^
  File "B:\disk\learn\project\NewsPortal\venv\Lib\site-packages\django\contrib\auth\mixins.py", line 109, in dispatch
    return super().dispatch(request, *args, **kwargs)
           ^^^^^^^^^^^^^^^^^^^^^^^^^^^^^^^^^^^^^^^^^^
  File "B:\disk\learn\project\NewsPortal\venv\Lib\site-packages\django\views\generic\base.py", line 143, in dispatch
    return handler(request, *args, **kwargs)
           ^^^^^^^^^^^^^^^^^^^^^^^^^^^^^^^^^
  File "B:\disk\learn\project\NewsPortal\venv\Lib\site-packages\django\views\generic\edit.py", line 184, in post
    return super().post(request, *args, **kwargs)
           ^^^^^^^^^^^^^^^^^^^^^^^^^^^^^^^^^^^^^^
  File "B:\disk\learn\project\NewsPortal\venv\Lib\site-packages\django\views\generic\edit.py", line 153, in post
    return self.form_valid(form)
           ^^^^^^^^^^^^^^^^^^^^^
  File "B:\disk\learn\project\NewsPortal\NewsPortal\NewsPortal\Models\views.py", line 76, in form_valid
    post.save()
  File "B:\disk\learn\project\NewsPortal\NewsPortal\NewsPortal\Models\models.py", line 85, in save
    super().save(self, force_insert, force_update, using, update_fields)
TypeError: Model.save() takes from 1 to 5 positional arguments but 6 were given
2024-08-17 21:38:27,053 ERROR "POST /models/news/create/ HTTP/1.1" 500 106319 None
2024-08-17 21:42:37,650 ERROR Internal Server Error: /models/news/create/ (<class 'TypeError'>, TypeError('Model.save() takes from 1 to 5 positional arguments but 6 were given'), <traceback object at 0x0000018A960A29C0>)
Traceback (most recent call last):
  File "B:\disk\learn\project\NewsPortal\venv\Lib\site-packages\django\core\handlers\exception.py", line 55, in inner
    response = get_response(request)
               ^^^^^^^^^^^^^^^^^^^^^
  File "B:\disk\learn\project\NewsPortal\venv\Lib\site-packages\django\core\handlers\base.py", line 197, in _get_response
    response = wrapped_callback(request, *callback_args, **callback_kwargs)
               ^^^^^^^^^^^^^^^^^^^^^^^^^^^^^^^^^^^^^^^^^^^^^^^^^^^^^^^^^^^^
  File "B:\disk\learn\project\NewsPortal\venv\Lib\site-packages\django\views\generic\base.py", line 104, in view
    return self.dispatch(request, *args, **kwargs)
           ^^^^^^^^^^^^^^^^^^^^^^^^^^^^^^^^^^^^^^^
  File "B:\disk\learn\project\NewsPortal\venv\Lib\site-packages\django\contrib\auth\mixins.py", line 109, in dispatch
    return super().dispatch(request, *args, **kwargs)
           ^^^^^^^^^^^^^^^^^^^^^^^^^^^^^^^^^^^^^^^^^^
  File "B:\disk\learn\project\NewsPortal\venv\Lib\site-packages\django\views\generic\base.py", line 143, in dispatch
    return handler(request, *args, **kwargs)
           ^^^^^^^^^^^^^^^^^^^^^^^^^^^^^^^^^
  File "B:\disk\learn\project\NewsPortal\venv\Lib\site-packages\django\views\generic\edit.py", line 184, in post
    return super().post(request, *args, **kwargs)
           ^^^^^^^^^^^^^^^^^^^^^^^^^^^^^^^^^^^^^^
  File "B:\disk\learn\project\NewsPortal\venv\Lib\site-packages\django\views\generic\edit.py", line 153, in post
    return self.form_valid(form)
           ^^^^^^^^^^^^^^^^^^^^^
  File "B:\disk\learn\project\NewsPortal\NewsPortal\NewsPortal\Models\views.py", line 76, in form_valid
    post.save()
  File "B:\disk\learn\project\NewsPortal\NewsPortal\NewsPortal\Models\models.py", line 85, in save
    super().save(self, force_insert, force_update, using, update_fields)
TypeError: Model.save() takes from 1 to 5 positional arguments but 6 were given
2024-08-17 21:42:37,674 ERROR "POST /models/news/create/ HTTP/1.1" 500 106324 None
2024-08-17 21:54:39,432 ERROR Internal Server Error: /models/news/create/ (<class 'kombu.exceptions.OperationalError'>, OperationalError('Error 10061 connecting to localhost:6379. Подключение не установлено, т.к. конечный компьютер отверг запрос на подключение.'), <traceback object at 0x0000022792320340>)
Traceback (most recent call last):
  File "B:\disk\learn\project\NewsPortal\venv\Lib\site-packages\redis\connection.py", line 264, in connect
    sock = self.retry.call_with_retry(
           ^^^^^^^^^^^^^^^^^^^^^^^^^^^
  File "B:\disk\learn\project\NewsPortal\venv\Lib\site-packages\redis\retry.py", line 46, in call_with_retry
    return do()
           ^^^^
  File "B:\disk\learn\project\NewsPortal\venv\Lib\site-packages\redis\connection.py", line 265, in <lambda>
    lambda: self._connect(), lambda error: self.disconnect(error)
            ^^^^^^^^^^^^^^^
  File "B:\disk\learn\project\NewsPortal\venv\Lib\site-packages\redis\connection.py", line 627, in _connect
    raise err
  File "B:\disk\learn\project\NewsPortal\venv\Lib\site-packages\redis\connection.py", line 615, in _connect
    sock.connect(socket_address)
ConnectionRefusedError: [WinError 10061] Подключение не установлено, т.к. конечный компьютер отверг запрос на подключение

During handling of the above exception, another exception occurred:

Traceback (most recent call last):
  File "B:\disk\learn\project\NewsPortal\venv\Lib\site-packages\celery\backends\redis.py", line 127, in reconnect_on_error
    yield
  File "B:\disk\learn\project\NewsPortal\venv\Lib\site-packages\celery\backends\redis.py", line 177, in _consume_from
    self._pubsub.subscribe(key)
  File "B:\disk\learn\project\NewsPortal\venv\Lib\site-packages\redis\client.py", line 916, in subscribe
    ret_val = self.execute_command("SUBSCRIBE", *new_channels.keys())
              ^^^^^^^^^^^^^^^^^^^^^^^^^^^^^^^^^^^^^^^^^^^^^^^^^^^^^^^
  File "B:\disk\learn\project\NewsPortal\venv\Lib\site-packages\redis\client.py", line 749, in execute_command
    self.connection = self.connection_pool.get_connection(
                      ^^^^^^^^^^^^^^^^^^^^^^^^^^^^^^^^^^^^
  File "B:\disk\learn\project\NewsPortal\venv\Lib\site-packages\redis\connection.py", line 1086, in get_connection
    connection.connect()
  File "B:\disk\learn\project\NewsPortal\venv\Lib\site-packages\redis\connection.py", line 270, in connect
    raise ConnectionError(self._error_message(e))
redis.exceptions.ConnectionError: Error 10061 connecting to localhost:6379. Подключение не установлено, т.к. конечный компьютер отверг запрос на подключение.

During handling of the above exception, another exception occurred:

Traceback (most recent call last):
  File "B:\disk\learn\project\NewsPortal\venv\Lib\site-packages\redis\connection.py", line 264, in connect
    sock = self.retry.call_with_retry(
           ^^^^^^^^^^^^^^^^^^^^^^^^^^^
  File "B:\disk\learn\project\NewsPortal\venv\Lib\site-packages\redis\retry.py", line 46, in call_with_retry
    return do()
           ^^^^
  File "B:\disk\learn\project\NewsPortal\venv\Lib\site-packages\redis\connection.py", line 265, in <lambda>
    lambda: self._connect(), lambda error: self.disconnect(error)
            ^^^^^^^^^^^^^^^
  File "B:\disk\learn\project\NewsPortal\venv\Lib\site-packages\redis\connection.py", line 627, in _connect
    raise err
  File "B:\disk\learn\project\NewsPortal\venv\Lib\site-packages\redis\connection.py", line 615, in _connect
    sock.connect(socket_address)
ConnectionRefusedError: [WinError 10061] Подключение не установлено, т.к. конечный компьютер отверг запрос на подключение

During handling of the above exception, another exception occurred:

Traceback (most recent call last):
  File "B:\disk\learn\project\NewsPortal\venv\Lib\site-packages\kombu\connection.py", line 472, in _reraise_as_library_errors
    yield
  File "B:\disk\learn\project\NewsPortal\venv\Lib\site-packages\celery\app\base.py", line 798, in send_task
    self.backend.on_task_call(P, task_id)
  File "B:\disk\learn\project\NewsPortal\venv\Lib\site-packages\celery\backends\redis.py", line 373, in on_task_call
    self.result_consumer.consume_from(task_id)
  File "B:\disk\learn\project\NewsPortal\venv\Lib\site-packages\celery\backends\redis.py", line 169, in consume_from
    return self.start(task_id)
           ^^^^^^^^^^^^^^^^^^^
  File "B:\disk\learn\project\NewsPortal\venv\Lib\site-packages\celery\backends\redis.py", line 147, in start
    self._consume_from(initial_task_id)
  File "B:\disk\learn\project\NewsPortal\venv\Lib\site-packages\celery\backends\redis.py", line 176, in _consume_from
    with self.reconnect_on_error():
  File "B:\Program Files\python\Lib\contextlib.py", line 155, in __exit__
    self.gen.throw(typ, value, traceback)
  File "B:\disk\learn\project\NewsPortal\venv\Lib\site-packages\celery\backends\redis.py", line 130, in reconnect_on_error
    self._ensure(self._reconnect_pubsub, ())
  File "B:\disk\learn\project\NewsPortal\venv\Lib\site-packages\celery\backends\redis.py", line 384, in ensure
    return retry_over_time(
           ^^^^^^^^^^^^^^^^
  File "B:\disk\learn\project\NewsPortal\venv\Lib\site-packages\kombu\utils\functional.py", line 318, in retry_over_time
    return fun(*args, **kwargs)
           ^^^^^^^^^^^^^^^^^^^^
  File "B:\disk\learn\project\NewsPortal\venv\Lib\site-packages\celery\backends\redis.py", line 106, in _reconnect_pubsub
    metas = self.backend.client.mget(self.subscribed_to)
            ^^^^^^^^^^^^^^^^^^^^^^^^^^^^^^^^^^^^^^^^^^^^
  File "B:\disk\learn\project\NewsPortal\venv\Lib\site-packages\redis\commands\core.py", line 2015, in mget
    return self.execute_command("MGET", *args, **options)
           ^^^^^^^^^^^^^^^^^^^^^^^^^^^^^^^^^^^^^^^^^^^^^^
  File "B:\disk\learn\project\NewsPortal\venv\Lib\site-packages\redis\client.py", line 533, in execute_command
    conn = self.connection or pool.get_connection(command_name, **options)
                              ^^^^^^^^^^^^^^^^^^^^^^^^^^^^^^^^^^^^^^^^^^^^
  File "B:\disk\learn\project\NewsPortal\venv\Lib\site-packages\redis\connection.py", line 1086, in get_connection
    connection.connect()
  File "B:\disk\learn\project\NewsPortal\venv\Lib\site-packages\redis\connection.py", line 270, in connect
    raise ConnectionError(self._error_message(e))
redis.exceptions.ConnectionError: Error 10061 connecting to localhost:6379. Подключение не установлено, т.к. конечный компьютер отверг запрос на подключение.

The above exception was the direct cause of the following exception:

Traceback (most recent call last):
  File "B:\disk\learn\project\NewsPortal\venv\Lib\site-packages\django\core\handlers\exception.py", line 55, in inner
    response = get_response(request)
               ^^^^^^^^^^^^^^^^^^^^^
  File "B:\disk\learn\project\NewsPortal\venv\Lib\site-packages\django\core\handlers\base.py", line 197, in _get_response
    response = wrapped_callback(request, *callback_args, **callback_kwargs)
               ^^^^^^^^^^^^^^^^^^^^^^^^^^^^^^^^^^^^^^^^^^^^^^^^^^^^^^^^^^^^
  File "B:\disk\learn\project\NewsPortal\venv\Lib\site-packages\django\views\generic\base.py", line 104, in view
    return self.dispatch(request, *args, **kwargs)
           ^^^^^^^^^^^^^^^^^^^^^^^^^^^^^^^^^^^^^^^
  File "B:\disk\learn\project\NewsPortal\venv\Lib\site-packages\django\contrib\auth\mixins.py", line 109, in dispatch
    return super().dispatch(request, *args, **kwargs)
           ^^^^^^^^^^^^^^^^^^^^^^^^^^^^^^^^^^^^^^^^^^
  File "B:\disk\learn\project\NewsPortal\venv\Lib\site-packages\django\views\generic\base.py", line 143, in dispatch
    return handler(request, *args, **kwargs)
           ^^^^^^^^^^^^^^^^^^^^^^^^^^^^^^^^^
  File "B:\disk\learn\project\NewsPortal\venv\Lib\site-packages\django\views\generic\edit.py", line 184, in post
    return super().post(request, *args, **kwargs)
           ^^^^^^^^^^^^^^^^^^^^^^^^^^^^^^^^^^^^^^
  File "B:\disk\learn\project\NewsPortal\venv\Lib\site-packages\django\views\generic\edit.py", line 153, in post
    return self.form_valid(form)
           ^^^^^^^^^^^^^^^^^^^^^
  File "B:\disk\learn\project\NewsPortal\NewsPortal\NewsPortal\Models\views.py", line 78, in form_valid
    create_post.delay(post.id)
  File "B:\disk\learn\project\NewsPortal\venv\Lib\site-packages\celery\app\task.py", line 444, in delay
    return self.apply_async(args, kwargs)
           ^^^^^^^^^^^^^^^^^^^^^^^^^^^^^^
  File "B:\disk\learn\project\NewsPortal\venv\Lib\site-packages\celery\app\task.py", line 594, in apply_async
    return app.send_task(
           ^^^^^^^^^^^^^^
  File "B:\disk\learn\project\NewsPortal\venv\Lib\site-packages\celery\app\base.py", line 796, in send_task
    with P.connection._reraise_as_library_errors():
  File "B:\Program Files\python\Lib\contextlib.py", line 155, in __exit__
    self.gen.throw(typ, value, traceback)
  File "B:\disk\learn\project\NewsPortal\venv\Lib\site-packages\kombu\connection.py", line 476, in _reraise_as_library_errors
    raise ConnectionError(str(exc)) from exc
kombu.exceptions.OperationalError: Error 10061 connecting to localhost:6379. Подключение не установлено, т.к. конечный компьютер отверг запрос на подключение.
2024-08-17 21:54:39,498 ERROR "POST /models/news/create/ HTTP/1.1" 500 288694 None
2024-08-17 21:59:18,666 ERROR Internal Server Error: /models/news/create/ (<class 'kombu.exceptions.OperationalError'>, OperationalError('Error 10061 connecting to localhost:6379. Подключение не установлено, т.к. конечный компьютер отверг запрос на подключение.'), <traceback object at 0x000002279235EBC0>)
Traceback (most recent call last):
  File "B:\disk\learn\project\NewsPortal\venv\Lib\site-packages\redis\connection.py", line 264, in connect
    sock = self.retry.call_with_retry(
           ^^^^^^^^^^^^^^^^^^^^^^^^^^^
  File "B:\disk\learn\project\NewsPortal\venv\Lib\site-packages\redis\retry.py", line 46, in call_with_retry
    return do()
           ^^^^
  File "B:\disk\learn\project\NewsPortal\venv\Lib\site-packages\redis\connection.py", line 265, in <lambda>
    lambda: self._connect(), lambda error: self.disconnect(error)
            ^^^^^^^^^^^^^^^
  File "B:\disk\learn\project\NewsPortal\venv\Lib\site-packages\redis\connection.py", line 627, in _connect
    raise err
  File "B:\disk\learn\project\NewsPortal\venv\Lib\site-packages\redis\connection.py", line 615, in _connect
    sock.connect(socket_address)
ConnectionRefusedError: [WinError 10061] Подключение не установлено, т.к. конечный компьютер отверг запрос на подключение

During handling of the above exception, another exception occurred:

Traceback (most recent call last):
  File "B:\disk\learn\project\NewsPortal\venv\Lib\site-packages\celery\backends\redis.py", line 127, in reconnect_on_error
    yield
  File "B:\disk\learn\project\NewsPortal\venv\Lib\site-packages\celery\backends\redis.py", line 177, in _consume_from
    self._pubsub.subscribe(key)
  File "B:\disk\learn\project\NewsPortal\venv\Lib\site-packages\redis\client.py", line 916, in subscribe
    ret_val = self.execute_command("SUBSCRIBE", *new_channels.keys())
              ^^^^^^^^^^^^^^^^^^^^^^^^^^^^^^^^^^^^^^^^^^^^^^^^^^^^^^^
  File "B:\disk\learn\project\NewsPortal\venv\Lib\site-packages\redis\client.py", line 749, in execute_command
    self.connection = self.connection_pool.get_connection(
                      ^^^^^^^^^^^^^^^^^^^^^^^^^^^^^^^^^^^^
  File "B:\disk\learn\project\NewsPortal\venv\Lib\site-packages\redis\connection.py", line 1086, in get_connection
    connection.connect()
  File "B:\disk\learn\project\NewsPortal\venv\Lib\site-packages\redis\connection.py", line 270, in connect
    raise ConnectionError(self._error_message(e))
redis.exceptions.ConnectionError: Error 10061 connecting to localhost:6379. Подключение не установлено, т.к. конечный компьютер отверг запрос на подключение.

During handling of the above exception, another exception occurred:

Traceback (most recent call last):
  File "B:\disk\learn\project\NewsPortal\venv\Lib\site-packages\redis\connection.py", line 264, in connect
    sock = self.retry.call_with_retry(
           ^^^^^^^^^^^^^^^^^^^^^^^^^^^
  File "B:\disk\learn\project\NewsPortal\venv\Lib\site-packages\redis\retry.py", line 46, in call_with_retry
    return do()
           ^^^^
  File "B:\disk\learn\project\NewsPortal\venv\Lib\site-packages\redis\connection.py", line 265, in <lambda>
    lambda: self._connect(), lambda error: self.disconnect(error)
            ^^^^^^^^^^^^^^^
  File "B:\disk\learn\project\NewsPortal\venv\Lib\site-packages\redis\connection.py", line 627, in _connect
    raise err
  File "B:\disk\learn\project\NewsPortal\venv\Lib\site-packages\redis\connection.py", line 615, in _connect
    sock.connect(socket_address)
ConnectionRefusedError: [WinError 10061] Подключение не установлено, т.к. конечный компьютер отверг запрос на подключение

During handling of the above exception, another exception occurred:

Traceback (most recent call last):
  File "B:\disk\learn\project\NewsPortal\venv\Lib\site-packages\kombu\connection.py", line 472, in _reraise_as_library_errors
    yield
  File "B:\disk\learn\project\NewsPortal\venv\Lib\site-packages\celery\app\base.py", line 798, in send_task
    self.backend.on_task_call(P, task_id)
  File "B:\disk\learn\project\NewsPortal\venv\Lib\site-packages\celery\backends\redis.py", line 373, in on_task_call
    self.result_consumer.consume_from(task_id)
  File "B:\disk\learn\project\NewsPortal\venv\Lib\site-packages\celery\backends\redis.py", line 169, in consume_from
    return self.start(task_id)
           ^^^^^^^^^^^^^^^^^^^
  File "B:\disk\learn\project\NewsPortal\venv\Lib\site-packages\celery\backends\redis.py", line 147, in start
    self._consume_from(initial_task_id)
  File "B:\disk\learn\project\NewsPortal\venv\Lib\site-packages\celery\backends\redis.py", line 176, in _consume_from
    with self.reconnect_on_error():
  File "B:\Program Files\python\Lib\contextlib.py", line 155, in __exit__
    self.gen.throw(typ, value, traceback)
  File "B:\disk\learn\project\NewsPortal\venv\Lib\site-packages\celery\backends\redis.py", line 130, in reconnect_on_error
    self._ensure(self._reconnect_pubsub, ())
  File "B:\disk\learn\project\NewsPortal\venv\Lib\site-packages\celery\backends\redis.py", line 384, in ensure
    return retry_over_time(
           ^^^^^^^^^^^^^^^^
  File "B:\disk\learn\project\NewsPortal\venv\Lib\site-packages\kombu\utils\functional.py", line 318, in retry_over_time
    return fun(*args, **kwargs)
           ^^^^^^^^^^^^^^^^^^^^
  File "B:\disk\learn\project\NewsPortal\venv\Lib\site-packages\celery\backends\redis.py", line 106, in _reconnect_pubsub
    metas = self.backend.client.mget(self.subscribed_to)
            ^^^^^^^^^^^^^^^^^^^^^^^^^^^^^^^^^^^^^^^^^^^^
  File "B:\disk\learn\project\NewsPortal\venv\Lib\site-packages\redis\commands\core.py", line 2015, in mget
    return self.execute_command("MGET", *args, **options)
           ^^^^^^^^^^^^^^^^^^^^^^^^^^^^^^^^^^^^^^^^^^^^^^
  File "B:\disk\learn\project\NewsPortal\venv\Lib\site-packages\redis\client.py", line 533, in execute_command
    conn = self.connection or pool.get_connection(command_name, **options)
                              ^^^^^^^^^^^^^^^^^^^^^^^^^^^^^^^^^^^^^^^^^^^^
  File "B:\disk\learn\project\NewsPortal\venv\Lib\site-packages\redis\connection.py", line 1086, in get_connection
    connection.connect()
  File "B:\disk\learn\project\NewsPortal\venv\Lib\site-packages\redis\connection.py", line 270, in connect
    raise ConnectionError(self._error_message(e))
redis.exceptions.ConnectionError: Error 10061 connecting to localhost:6379. Подключение не установлено, т.к. конечный компьютер отверг запрос на подключение.

The above exception was the direct cause of the following exception:

Traceback (most recent call last):
  File "B:\disk\learn\project\NewsPortal\venv\Lib\site-packages\django\core\handlers\exception.py", line 55, in inner
    response = get_response(request)
               ^^^^^^^^^^^^^^^^^^^^^
  File "B:\disk\learn\project\NewsPortal\venv\Lib\site-packages\django\core\handlers\base.py", line 197, in _get_response
    response = wrapped_callback(request, *callback_args, **callback_kwargs)
               ^^^^^^^^^^^^^^^^^^^^^^^^^^^^^^^^^^^^^^^^^^^^^^^^^^^^^^^^^^^^
  File "B:\disk\learn\project\NewsPortal\venv\Lib\site-packages\django\views\generic\base.py", line 104, in view
    return self.dispatch(request, *args, **kwargs)
           ^^^^^^^^^^^^^^^^^^^^^^^^^^^^^^^^^^^^^^^
  File "B:\disk\learn\project\NewsPortal\venv\Lib\site-packages\django\contrib\auth\mixins.py", line 109, in dispatch
    return super().dispatch(request, *args, **kwargs)
           ^^^^^^^^^^^^^^^^^^^^^^^^^^^^^^^^^^^^^^^^^^
  File "B:\disk\learn\project\NewsPortal\venv\Lib\site-packages\django\views\generic\base.py", line 143, in dispatch
    return handler(request, *args, **kwargs)
           ^^^^^^^^^^^^^^^^^^^^^^^^^^^^^^^^^
  File "B:\disk\learn\project\NewsPortal\venv\Lib\site-packages\django\views\generic\edit.py", line 184, in post
    return super().post(request, *args, **kwargs)
           ^^^^^^^^^^^^^^^^^^^^^^^^^^^^^^^^^^^^^^
  File "B:\disk\learn\project\NewsPortal\venv\Lib\site-packages\django\views\generic\edit.py", line 153, in post
    return self.form_valid(form)
           ^^^^^^^^^^^^^^^^^^^^^
  File "B:\disk\learn\project\NewsPortal\NewsPortal\NewsPortal\Models\views.py", line 78, in form_valid
    create_post.delay(post.id)
  File "B:\disk\learn\project\NewsPortal\venv\Lib\site-packages\celery\app\task.py", line 444, in delay
    return self.apply_async(args, kwargs)
           ^^^^^^^^^^^^^^^^^^^^^^^^^^^^^^
  File "B:\disk\learn\project\NewsPortal\venv\Lib\site-packages\celery\app\task.py", line 594, in apply_async
    return app.send_task(
           ^^^^^^^^^^^^^^
  File "B:\disk\learn\project\NewsPortal\venv\Lib\site-packages\celery\app\base.py", line 796, in send_task
    with P.connection._reraise_as_library_errors():
  File "B:\Program Files\python\Lib\contextlib.py", line 155, in __exit__
    self.gen.throw(typ, value, traceback)
  File "B:\disk\learn\project\NewsPortal\venv\Lib\site-packages\kombu\connection.py", line 476, in _reraise_as_library_errors
    raise ConnectionError(str(exc)) from exc
kombu.exceptions.OperationalError: Error 10061 connecting to localhost:6379. Подключение не установлено, т.к. конечный компьютер отверг запрос на подключение.
2024-08-17 21:59:18,731 ERROR "POST /models/news/create/ HTTP/1.1" 500 288694 None
2024-08-17 22:00:16,198 ERROR Internal Server Error: /models/news/create/ (<class 'kombu.exceptions.OperationalError'>, OperationalError('Error 10061 connecting to localhost:6379. Подключение не установлено, т.к. конечный компьютер отверг запрос на подключение.'), <traceback object at 0x0000022793814340>)
Traceback (most recent call last):
  File "B:\disk\learn\project\NewsPortal\venv\Lib\site-packages\redis\connection.py", line 264, in connect
    sock = self.retry.call_with_retry(
           ^^^^^^^^^^^^^^^^^^^^^^^^^^^
  File "B:\disk\learn\project\NewsPortal\venv\Lib\site-packages\redis\retry.py", line 46, in call_with_retry
    return do()
           ^^^^
  File "B:\disk\learn\project\NewsPortal\venv\Lib\site-packages\redis\connection.py", line 265, in <lambda>
    lambda: self._connect(), lambda error: self.disconnect(error)
            ^^^^^^^^^^^^^^^
  File "B:\disk\learn\project\NewsPortal\venv\Lib\site-packages\redis\connection.py", line 627, in _connect
    raise err
  File "B:\disk\learn\project\NewsPortal\venv\Lib\site-packages\redis\connection.py", line 615, in _connect
    sock.connect(socket_address)
ConnectionRefusedError: [WinError 10061] Подключение не установлено, т.к. конечный компьютер отверг запрос на подключение

During handling of the above exception, another exception occurred:

Traceback (most recent call last):
  File "B:\disk\learn\project\NewsPortal\venv\Lib\site-packages\celery\backends\redis.py", line 127, in reconnect_on_error
    yield
  File "B:\disk\learn\project\NewsPortal\venv\Lib\site-packages\celery\backends\redis.py", line 177, in _consume_from
    self._pubsub.subscribe(key)
  File "B:\disk\learn\project\NewsPortal\venv\Lib\site-packages\redis\client.py", line 916, in subscribe
    ret_val = self.execute_command("SUBSCRIBE", *new_channels.keys())
              ^^^^^^^^^^^^^^^^^^^^^^^^^^^^^^^^^^^^^^^^^^^^^^^^^^^^^^^
  File "B:\disk\learn\project\NewsPortal\venv\Lib\site-packages\redis\client.py", line 749, in execute_command
    self.connection = self.connection_pool.get_connection(
                      ^^^^^^^^^^^^^^^^^^^^^^^^^^^^^^^^^^^^
  File "B:\disk\learn\project\NewsPortal\venv\Lib\site-packages\redis\connection.py", line 1086, in get_connection
    connection.connect()
  File "B:\disk\learn\project\NewsPortal\venv\Lib\site-packages\redis\connection.py", line 270, in connect
    raise ConnectionError(self._error_message(e))
redis.exceptions.ConnectionError: Error 10061 connecting to localhost:6379. Подключение не установлено, т.к. конечный компьютер отверг запрос на подключение.

During handling of the above exception, another exception occurred:

Traceback (most recent call last):
  File "B:\disk\learn\project\NewsPortal\venv\Lib\site-packages\redis\connection.py", line 264, in connect
    sock = self.retry.call_with_retry(
           ^^^^^^^^^^^^^^^^^^^^^^^^^^^
  File "B:\disk\learn\project\NewsPortal\venv\Lib\site-packages\redis\retry.py", line 46, in call_with_retry
    return do()
           ^^^^
  File "B:\disk\learn\project\NewsPortal\venv\Lib\site-packages\redis\connection.py", line 265, in <lambda>
    lambda: self._connect(), lambda error: self.disconnect(error)
            ^^^^^^^^^^^^^^^
  File "B:\disk\learn\project\NewsPortal\venv\Lib\site-packages\redis\connection.py", line 627, in _connect
    raise err
  File "B:\disk\learn\project\NewsPortal\venv\Lib\site-packages\redis\connection.py", line 615, in _connect
    sock.connect(socket_address)
ConnectionRefusedError: [WinError 10061] Подключение не установлено, т.к. конечный компьютер отверг запрос на подключение

During handling of the above exception, another exception occurred:

Traceback (most recent call last):
  File "B:\disk\learn\project\NewsPortal\venv\Lib\site-packages\kombu\connection.py", line 472, in _reraise_as_library_errors
    yield
  File "B:\disk\learn\project\NewsPortal\venv\Lib\site-packages\celery\app\base.py", line 798, in send_task
    self.backend.on_task_call(P, task_id)
  File "B:\disk\learn\project\NewsPortal\venv\Lib\site-packages\celery\backends\redis.py", line 373, in on_task_call
    self.result_consumer.consume_from(task_id)
  File "B:\disk\learn\project\NewsPortal\venv\Lib\site-packages\celery\backends\redis.py", line 169, in consume_from
    return self.start(task_id)
           ^^^^^^^^^^^^^^^^^^^
  File "B:\disk\learn\project\NewsPortal\venv\Lib\site-packages\celery\backends\redis.py", line 147, in start
    self._consume_from(initial_task_id)
  File "B:\disk\learn\project\NewsPortal\venv\Lib\site-packages\celery\backends\redis.py", line 176, in _consume_from
    with self.reconnect_on_error():
  File "B:\Program Files\python\Lib\contextlib.py", line 155, in __exit__
    self.gen.throw(typ, value, traceback)
  File "B:\disk\learn\project\NewsPortal\venv\Lib\site-packages\celery\backends\redis.py", line 130, in reconnect_on_error
    self._ensure(self._reconnect_pubsub, ())
  File "B:\disk\learn\project\NewsPortal\venv\Lib\site-packages\celery\backends\redis.py", line 384, in ensure
    return retry_over_time(
           ^^^^^^^^^^^^^^^^
  File "B:\disk\learn\project\NewsPortal\venv\Lib\site-packages\kombu\utils\functional.py", line 318, in retry_over_time
    return fun(*args, **kwargs)
           ^^^^^^^^^^^^^^^^^^^^
  File "B:\disk\learn\project\NewsPortal\venv\Lib\site-packages\celery\backends\redis.py", line 106, in _reconnect_pubsub
    metas = self.backend.client.mget(self.subscribed_to)
            ^^^^^^^^^^^^^^^^^^^^^^^^^^^^^^^^^^^^^^^^^^^^
  File "B:\disk\learn\project\NewsPortal\venv\Lib\site-packages\redis\commands\core.py", line 2015, in mget
    return self.execute_command("MGET", *args, **options)
           ^^^^^^^^^^^^^^^^^^^^^^^^^^^^^^^^^^^^^^^^^^^^^^
  File "B:\disk\learn\project\NewsPortal\venv\Lib\site-packages\redis\client.py", line 533, in execute_command
    conn = self.connection or pool.get_connection(command_name, **options)
                              ^^^^^^^^^^^^^^^^^^^^^^^^^^^^^^^^^^^^^^^^^^^^
  File "B:\disk\learn\project\NewsPortal\venv\Lib\site-packages\redis\connection.py", line 1086, in get_connection
    connection.connect()
  File "B:\disk\learn\project\NewsPortal\venv\Lib\site-packages\redis\connection.py", line 270, in connect
    raise ConnectionError(self._error_message(e))
redis.exceptions.ConnectionError: Error 10061 connecting to localhost:6379. Подключение не установлено, т.к. конечный компьютер отверг запрос на подключение.

The above exception was the direct cause of the following exception:

Traceback (most recent call last):
  File "B:\disk\learn\project\NewsPortal\venv\Lib\site-packages\django\core\handlers\exception.py", line 55, in inner
    response = get_response(request)
               ^^^^^^^^^^^^^^^^^^^^^
  File "B:\disk\learn\project\NewsPortal\venv\Lib\site-packages\django\core\handlers\base.py", line 197, in _get_response
    response = wrapped_callback(request, *callback_args, **callback_kwargs)
               ^^^^^^^^^^^^^^^^^^^^^^^^^^^^^^^^^^^^^^^^^^^^^^^^^^^^^^^^^^^^
  File "B:\disk\learn\project\NewsPortal\venv\Lib\site-packages\django\views\generic\base.py", line 104, in view
    return self.dispatch(request, *args, **kwargs)
           ^^^^^^^^^^^^^^^^^^^^^^^^^^^^^^^^^^^^^^^
  File "B:\disk\learn\project\NewsPortal\venv\Lib\site-packages\django\contrib\auth\mixins.py", line 109, in dispatch
    return super().dispatch(request, *args, **kwargs)
           ^^^^^^^^^^^^^^^^^^^^^^^^^^^^^^^^^^^^^^^^^^
  File "B:\disk\learn\project\NewsPortal\venv\Lib\site-packages\django\views\generic\base.py", line 143, in dispatch
    return handler(request, *args, **kwargs)
           ^^^^^^^^^^^^^^^^^^^^^^^^^^^^^^^^^
  File "B:\disk\learn\project\NewsPortal\venv\Lib\site-packages\django\views\generic\edit.py", line 184, in post
    return super().post(request, *args, **kwargs)
           ^^^^^^^^^^^^^^^^^^^^^^^^^^^^^^^^^^^^^^
  File "B:\disk\learn\project\NewsPortal\venv\Lib\site-packages\django\views\generic\edit.py", line 153, in post
    return self.form_valid(form)
           ^^^^^^^^^^^^^^^^^^^^^
  File "B:\disk\learn\project\NewsPortal\NewsPortal\NewsPortal\Models\views.py", line 78, in form_valid
    create_post.delay(post.id)
  File "B:\disk\learn\project\NewsPortal\venv\Lib\site-packages\celery\app\task.py", line 444, in delay
    return self.apply_async(args, kwargs)
           ^^^^^^^^^^^^^^^^^^^^^^^^^^^^^^
  File "B:\disk\learn\project\NewsPortal\venv\Lib\site-packages\celery\app\task.py", line 594, in apply_async
    return app.send_task(
           ^^^^^^^^^^^^^^
  File "B:\disk\learn\project\NewsPortal\venv\Lib\site-packages\celery\app\base.py", line 796, in send_task
    with P.connection._reraise_as_library_errors():
  File "B:\Program Files\python\Lib\contextlib.py", line 155, in __exit__
    self.gen.throw(typ, value, traceback)
  File "B:\disk\learn\project\NewsPortal\venv\Lib\site-packages\kombu\connection.py", line 476, in _reraise_as_library_errors
    raise ConnectionError(str(exc)) from exc
kombu.exceptions.OperationalError: Error 10061 connecting to localhost:6379. Подключение не установлено, т.к. конечный компьютер отверг запрос на подключение.
2024-08-17 22:00:16,263 ERROR "POST /models/news/create/ HTTP/1.1" 500 288694 None
2024-08-17 22:00:30,843 ERROR Internal Server Error: /models/news/create/ (<class 'kombu.exceptions.OperationalError'>, OperationalError('Error 10061 connecting to localhost:6379. Подключение не установлено, т.к. конечный компьютер отверг запрос на подключение.'), <traceback object at 0x00000227937A0440>)
Traceback (most recent call last):
  File "B:\disk\learn\project\NewsPortal\venv\Lib\site-packages\redis\connection.py", line 264, in connect
    sock = self.retry.call_with_retry(
           ^^^^^^^^^^^^^^^^^^^^^^^^^^^
  File "B:\disk\learn\project\NewsPortal\venv\Lib\site-packages\redis\retry.py", line 46, in call_with_retry
    return do()
           ^^^^
  File "B:\disk\learn\project\NewsPortal\venv\Lib\site-packages\redis\connection.py", line 265, in <lambda>
    lambda: self._connect(), lambda error: self.disconnect(error)
            ^^^^^^^^^^^^^^^
  File "B:\disk\learn\project\NewsPortal\venv\Lib\site-packages\redis\connection.py", line 627, in _connect
    raise err
  File "B:\disk\learn\project\NewsPortal\venv\Lib\site-packages\redis\connection.py", line 615, in _connect
    sock.connect(socket_address)
ConnectionRefusedError: [WinError 10061] Подключение не установлено, т.к. конечный компьютер отверг запрос на подключение

During handling of the above exception, another exception occurred:

Traceback (most recent call last):
  File "B:\disk\learn\project\NewsPortal\venv\Lib\site-packages\celery\backends\redis.py", line 127, in reconnect_on_error
    yield
  File "B:\disk\learn\project\NewsPortal\venv\Lib\site-packages\celery\backends\redis.py", line 177, in _consume_from
    self._pubsub.subscribe(key)
  File "B:\disk\learn\project\NewsPortal\venv\Lib\site-packages\redis\client.py", line 916, in subscribe
    ret_val = self.execute_command("SUBSCRIBE", *new_channels.keys())
              ^^^^^^^^^^^^^^^^^^^^^^^^^^^^^^^^^^^^^^^^^^^^^^^^^^^^^^^
  File "B:\disk\learn\project\NewsPortal\venv\Lib\site-packages\redis\client.py", line 749, in execute_command
    self.connection = self.connection_pool.get_connection(
                      ^^^^^^^^^^^^^^^^^^^^^^^^^^^^^^^^^^^^
  File "B:\disk\learn\project\NewsPortal\venv\Lib\site-packages\redis\connection.py", line 1086, in get_connection
    connection.connect()
  File "B:\disk\learn\project\NewsPortal\venv\Lib\site-packages\redis\connection.py", line 270, in connect
    raise ConnectionError(self._error_message(e))
redis.exceptions.ConnectionError: Error 10061 connecting to localhost:6379. Подключение не установлено, т.к. конечный компьютер отверг запрос на подключение.

During handling of the above exception, another exception occurred:

Traceback (most recent call last):
  File "B:\disk\learn\project\NewsPortal\venv\Lib\site-packages\redis\connection.py", line 264, in connect
    sock = self.retry.call_with_retry(
           ^^^^^^^^^^^^^^^^^^^^^^^^^^^
  File "B:\disk\learn\project\NewsPortal\venv\Lib\site-packages\redis\retry.py", line 46, in call_with_retry
    return do()
           ^^^^
  File "B:\disk\learn\project\NewsPortal\venv\Lib\site-packages\redis\connection.py", line 265, in <lambda>
    lambda: self._connect(), lambda error: self.disconnect(error)
            ^^^^^^^^^^^^^^^
  File "B:\disk\learn\project\NewsPortal\venv\Lib\site-packages\redis\connection.py", line 627, in _connect
    raise err
  File "B:\disk\learn\project\NewsPortal\venv\Lib\site-packages\redis\connection.py", line 615, in _connect
    sock.connect(socket_address)
ConnectionRefusedError: [WinError 10061] Подключение не установлено, т.к. конечный компьютер отверг запрос на подключение

During handling of the above exception, another exception occurred:

Traceback (most recent call last):
  File "B:\disk\learn\project\NewsPortal\venv\Lib\site-packages\kombu\connection.py", line 472, in _reraise_as_library_errors
    yield
  File "B:\disk\learn\project\NewsPortal\venv\Lib\site-packages\celery\app\base.py", line 798, in send_task
    self.backend.on_task_call(P, task_id)
  File "B:\disk\learn\project\NewsPortal\venv\Lib\site-packages\celery\backends\redis.py", line 373, in on_task_call
    self.result_consumer.consume_from(task_id)
  File "B:\disk\learn\project\NewsPortal\venv\Lib\site-packages\celery\backends\redis.py", line 169, in consume_from
    return self.start(task_id)
           ^^^^^^^^^^^^^^^^^^^
  File "B:\disk\learn\project\NewsPortal\venv\Lib\site-packages\celery\backends\redis.py", line 147, in start
    self._consume_from(initial_task_id)
  File "B:\disk\learn\project\NewsPortal\venv\Lib\site-packages\celery\backends\redis.py", line 176, in _consume_from
    with self.reconnect_on_error():
  File "B:\Program Files\python\Lib\contextlib.py", line 155, in __exit__
    self.gen.throw(typ, value, traceback)
  File "B:\disk\learn\project\NewsPortal\venv\Lib\site-packages\celery\backends\redis.py", line 130, in reconnect_on_error
    self._ensure(self._reconnect_pubsub, ())
  File "B:\disk\learn\project\NewsPortal\venv\Lib\site-packages\celery\backends\redis.py", line 384, in ensure
    return retry_over_time(
           ^^^^^^^^^^^^^^^^
  File "B:\disk\learn\project\NewsPortal\venv\Lib\site-packages\kombu\utils\functional.py", line 318, in retry_over_time
    return fun(*args, **kwargs)
           ^^^^^^^^^^^^^^^^^^^^
  File "B:\disk\learn\project\NewsPortal\venv\Lib\site-packages\celery\backends\redis.py", line 106, in _reconnect_pubsub
    metas = self.backend.client.mget(self.subscribed_to)
            ^^^^^^^^^^^^^^^^^^^^^^^^^^^^^^^^^^^^^^^^^^^^
  File "B:\disk\learn\project\NewsPortal\venv\Lib\site-packages\redis\commands\core.py", line 2015, in mget
    return self.execute_command("MGET", *args, **options)
           ^^^^^^^^^^^^^^^^^^^^^^^^^^^^^^^^^^^^^^^^^^^^^^
  File "B:\disk\learn\project\NewsPortal\venv\Lib\site-packages\redis\client.py", line 533, in execute_command
    conn = self.connection or pool.get_connection(command_name, **options)
                              ^^^^^^^^^^^^^^^^^^^^^^^^^^^^^^^^^^^^^^^^^^^^
  File "B:\disk\learn\project\NewsPortal\venv\Lib\site-packages\redis\connection.py", line 1086, in get_connection
    connection.connect()
  File "B:\disk\learn\project\NewsPortal\venv\Lib\site-packages\redis\connection.py", line 270, in connect
    raise ConnectionError(self._error_message(e))
redis.exceptions.ConnectionError: Error 10061 connecting to localhost:6379. Подключение не установлено, т.к. конечный компьютер отверг запрос на подключение.

The above exception was the direct cause of the following exception:

Traceback (most recent call last):
  File "B:\disk\learn\project\NewsPortal\venv\Lib\site-packages\django\core\handlers\exception.py", line 55, in inner
    response = get_response(request)
               ^^^^^^^^^^^^^^^^^^^^^
  File "B:\disk\learn\project\NewsPortal\venv\Lib\site-packages\django\core\handlers\base.py", line 197, in _get_response
    response = wrapped_callback(request, *callback_args, **callback_kwargs)
               ^^^^^^^^^^^^^^^^^^^^^^^^^^^^^^^^^^^^^^^^^^^^^^^^^^^^^^^^^^^^
  File "B:\disk\learn\project\NewsPortal\venv\Lib\site-packages\django\views\generic\base.py", line 104, in view
    return self.dispatch(request, *args, **kwargs)
           ^^^^^^^^^^^^^^^^^^^^^^^^^^^^^^^^^^^^^^^
  File "B:\disk\learn\project\NewsPortal\venv\Lib\site-packages\django\contrib\auth\mixins.py", line 109, in dispatch
    return super().dispatch(request, *args, **kwargs)
           ^^^^^^^^^^^^^^^^^^^^^^^^^^^^^^^^^^^^^^^^^^
  File "B:\disk\learn\project\NewsPortal\venv\Lib\site-packages\django\views\generic\base.py", line 143, in dispatch
    return handler(request, *args, **kwargs)
           ^^^^^^^^^^^^^^^^^^^^^^^^^^^^^^^^^
  File "B:\disk\learn\project\NewsPortal\venv\Lib\site-packages\django\views\generic\edit.py", line 184, in post
    return super().post(request, *args, **kwargs)
           ^^^^^^^^^^^^^^^^^^^^^^^^^^^^^^^^^^^^^^
  File "B:\disk\learn\project\NewsPortal\venv\Lib\site-packages\django\views\generic\edit.py", line 153, in post
    return self.form_valid(form)
           ^^^^^^^^^^^^^^^^^^^^^
  File "B:\disk\learn\project\NewsPortal\NewsPortal\NewsPortal\Models\views.py", line 78, in form_valid
    create_post.delay(post.id)
  File "B:\disk\learn\project\NewsPortal\venv\Lib\site-packages\celery\app\task.py", line 444, in delay
    return self.apply_async(args, kwargs)
           ^^^^^^^^^^^^^^^^^^^^^^^^^^^^^^
  File "B:\disk\learn\project\NewsPortal\venv\Lib\site-packages\celery\app\task.py", line 594, in apply_async
    return app.send_task(
           ^^^^^^^^^^^^^^
  File "B:\disk\learn\project\NewsPortal\venv\Lib\site-packages\celery\app\base.py", line 796, in send_task
    with P.connection._reraise_as_library_errors():
  File "B:\Program Files\python\Lib\contextlib.py", line 155, in __exit__
    self.gen.throw(typ, value, traceback)
  File "B:\disk\learn\project\NewsPortal\venv\Lib\site-packages\kombu\connection.py", line 476, in _reraise_as_library_errors
    raise ConnectionError(str(exc)) from exc
kombu.exceptions.OperationalError: Error 10061 connecting to localhost:6379. Подключение не установлено, т.к. конечный компьютер отверг запрос на подключение.
2024-08-17 22:00:30,899 ERROR "POST /models/news/create/ HTTP/1.1" 500 288696 None
2024-08-18 00:20:32,981 ERROR Internal Server Error: /models/test/ None
2024-08-18 00:20:33,004 ERROR "GET /models/test/ HTTP/1.1" 500 0 None
2024-08-18 00:24:15,114 ERROR Internal Server Error: /models/test/ None
2024-08-18 00:24:15,139 ERROR "GET /models/test/ HTTP/1.1" 500 59 None
2024-08-18 00:25:44,777 ERROR Internal Server Error: /models/test/ None
2024-08-18 00:25:44,792 ERROR "GET /models/test/ HTTP/1.1" 500 59 None
2024-08-18 00:26:03,454 ERROR Internal Server Error: /models/test/ None
2024-08-18 00:26:03,480 ERROR "GET /models/test/ HTTP/1.1" 500 59 None
2024-08-18 00:30:11,459 ERROR Internal Server Error: /models/test/ None
2024-08-18 00:30:11,485 ERROR "GET /models/test/ HTTP/1.1" 500 59 None
2024-08-18 00:31:18,335 ERROR Internal Server Error: /models/test/ None
2024-08-18 00:31:18,361 ERROR "GET /models/test/ HTTP/1.1" 500 59 None
2024-08-18 00:31:52,836 ERROR Internal Server Error: /models/test/ None
2024-08-18 00:31:52,862 ERROR "GET /models/test/ HTTP/1.1" 500 59 None
2024-08-18 00:33:04,085 ERROR Internal Server Error: /models/test/ None
2024-08-18 00:33:04,100 ERROR "GET /models/test/ HTTP/1.1" 500 59 None
2024-08-18 00:35:32,918 ERROR Internal Server Error: /models/test/ None
2024-08-18 00:35:32,944 ERROR "GET /models/test/ HTTP/1.1" 500 59 None
2024-08-18 00:36:13,169 ERROR Internal Server Error: /models/test/ None
2024-08-18 00:36:13,194 ERROR "GET /models/test/ HTTP/1.1" 500 59 None
2024-08-18 00:41:23,891 ERROR Internal Server Error: /models/test/ None
2024-08-18 00:41:23,921 ERROR "GET /models/test/ HTTP/1.1" 500 59 None
2024-08-18 00:47:31,778 ERROR Internal Server Error: /models/test/ None
2024-08-18 00:47:31,804 ERROR "GET /models/test/ HTTP/1.1" 500 59 None
2024-08-18 00:49:13,674 ERROR Internal Server Error: /models/test/ None
2024-08-18 00:49:13,705 ERROR "GET /models/test/ HTTP/1.1" 500 59 None
2024-08-18 00:52:28,866 ERROR Internal Server Error: /models/test/ None
2024-08-18 00:52:28,892 ERROR "GET /models/test/ HTTP/1.1" 500 59 None
2024-08-18 00:55:51,159 ERROR Internal Server Error: /models/test/ None
2024-08-18 00:55:51,187 ERROR "GET /models/test/ HTTP/1.1" 500 59 None
2024-08-18 00:56:53,121 ERROR Internal Server Error: /models/test/ None
2024-08-18 00:56:54,847 ERROR "GET /models/test/ HTTP/1.1" 500 0 None
2024-08-18 00:57:52,941 ERROR Internal Server Error: /models/test/ None
2024-08-18 00:57:54,172 ERROR "GET /models/test/ HTTP/1.1" 500 0 None
2024-08-18 00:58:47,653 ERROR Internal Server Error: /models/test/ None
2024-08-18 00:58:48,006 ERROR "GET /models/test/ HTTP/1.1" 500 0 None
2024-08-18 01:00:11,465 ERROR Internal Server Error: /models/test/ None
2024-08-18 01:00:14,062 ERROR "GET /models/test/ HTTP/1.1" 500 0 None
2024-08-18 01:04:18,562 ERROR Internal Server Error: /models/test/ None
2024-08-18 01:04:20,052 ERROR "GET /models/test/ HTTP/1.1" 500 0 None
2024-08-18 01:05:30,916 ERROR Internal Server Error: /models/test/ None
2024-08-18 01:05:33,073 ERROR "GET /models/test/ HTTP/1.1" 500 0 None
2024-08-18 01:10:16,151 ERROR Internal Server Error: /models/test/ None
2024-08-18 01:10:16,838 ERROR "GET /models/test/ HTTP/1.1" 500 0 None
2024-08-18 01:11:20,411 ERROR Internal Server Error: /models/test/ None
2024-08-18 01:11:22,232 ERROR "GET /models/test/ HTTP/1.1" 500 0 None
2024-08-18 01:12:39,265 ERROR Internal Server Error: /models/test/ None
2024-08-18 01:12:40,232 ERROR "GET /models/test/ HTTP/1.1" 500 0 None
2024-08-18 01:13:29,956 ERROR Internal Server Error: /models/test/ None
2024-08-18 01:13:30,374 ERROR "GET /models/test/ HTTP/1.1" 500 0 None
2024-08-18 01:14:08,306 ERROR Internal Server Error: /models/test/ None
2024-08-18 01:14:08,666 ERROR "GET /models/test/ HTTP/1.1" 500 0 None
2024-08-18 01:15:22,472 ERROR Internal Server Error: /models/test/ None
2024-08-18 01:15:23,484 ERROR "GET /models/test/ HTTP/1.1" 500 0 None
2024-08-18 01:16:53,124 ERROR Internal Server Error: /models/test/ None
2024-08-18 01:16:53,523 ERROR "GET /models/test/ HTTP/1.1" 500 0 None
2024-08-18 01:18:13,795 ERROR Internal Server Error: /models/test/ None
2024-08-18 01:18:15,828 ERROR "GET /models/test/ HTTP/1.1" 500 0 None
2024-08-18 01:18:58,252 ERROR Internal Server Error: /models/test/ None
2024-08-18 01:18:58,312 ERROR "GET /models/test/ HTTP/1.1" 500 59 None
2024-08-18 01:21:18,628 ERROR Internal Server Error: /models/test/ None
2024-08-18 01:21:19,050 ERROR "GET /models/test/ HTTP/1.1" 500 0 None
2024-08-18 01:24:55,046 ERROR Internal Server Error: /models/test/ None
2024-08-18 01:24:59,244 ERROR "GET /models/test/ HTTP/1.1" 500 0 None
2024-08-18 01:26:42,068 ERROR Internal Server Error: /models/test/ None
2024-08-18 01:26:46,770 ERROR "GET /models/test/ HTTP/1.1" 500 0 None
2024-08-18 01:33:12,144 ERROR Internal Server Error: /models/test/ None
2024-08-18 01:33:12,899 ERROR "GET /models/test/ HTTP/1.1" 500 0 None
2024-08-18 01:34:10,749 ERROR Internal Server Error: /models/test/ None
2024-08-18 01:34:11,162 ERROR "GET /models/test/ HTTP/1.1" 500 0 None
2024-08-18 01:34:47,823 ERROR Internal Server Error: /models/test/ None
2024-08-18 01:34:48,872 ERROR "GET /models/test/ HTTP/1.1" 500 0 None
2024-08-18 01:47:56,783 ERROR Internal Server Error: /models/test/ None
2024-08-18 01:47:58,325 ERROR "GET /models/test/ HTTP/1.1" 500 0 None
2024-08-18 01:57:00,001 ERROR Internal Server Error: /models/test/ None
2024-08-18 01:57:00,401 ERROR "GET /models/test/ HTTP/1.1" 500 0 None
2024-08-18 01:57:58,598 ERROR Internal Server Error: /models/test/ None
2024-08-18 01:57:58,969 ERROR "GET /models/test/ HTTP/1.1" 500 0 None
2024-08-18 02:07:00,134 ERROR Internal Server Error: /models/test/ None
2024-08-18 02:07:01,018 ERROR "GET /models/test/ HTTP/1.1" 500 0 None
2024-08-18 02:11:31,584 ERROR Internal Server Error: /models/test/ None
2024-08-22 22:11:11,622 ERROR Internal Server Error: /models/test/ None
2024-08-22 22:11:17,384 ERROR "GET /models/test/ HTTP/1.1" 500 0 None
2024-08-22 22:47:00,013 ERROR Internal Server Error: /models/test/ None
2024-08-22 22:47:00,015 ERROR "GET /models/test/ HTTP/1.1" 500 0 None
2024-08-22 22:47:00,325 ERROR Internal Server Error: /models/test/ None
2024-08-22 22:47:00,328 ERROR "GET /models/test/ HTTP/1.1" 500 0 None
2024-08-22 22:48:25,116 ERROR Internal Server Error: /models/test/ None
2024-08-22 22:48:52,642 ERROR Internal Server Error: /models/test/ None
2024-08-22 22:48:52,655 ERROR "GET /models/test/ HTTP/1.1" 500 0 None
2024-08-22 22:49:12,432 ERROR Internal Server Error: /models/test/ None
2024-08-22 22:49:28,412 ERROR "GET /models/test/ HTTP/1.1" 500 0 None
